Workbook
Name cfg_arm1: Settings!$B$7
Name cfg_arm2: Settings!$B$8
Name cfg_arm3: Settings!$B$9
Name cfg_base: Settings!$B$16
Name cfg_concurrent: Settings!$B$6
Name cfg_days: Settings!$B$25
Name cfg_exp: Settings!$B$18
Name cfg_hoursday: Settings!$B$26
Name cfg_mend: Settings!$B$20
Name cfg_mkey: Settings!$B$19
Name cfg_mskip: Settings!$B$21
Name cfg_overhead: Settings!$B$11
Name cfg_pct: Settings!$B$12
Name cfg_ratemult: Settings!$B$10
Name cfg_roster: Settings!$B$5
Name cfg_slope: Settings!$B$17
Name cfg_window: Settings!$B$27
Name list_agility_lap: agility_lap!$A$5:$A$53
Name list_clue_completion: clue_completion!$A$5:$A$40
Name list_gp_value: gp_value!$A$5:$A$92
Name list_item_drop: item_drop!$A$5:$A$329
Name list_minigame_completion: minigame_completion!$A$5:$A$47
Name list_npc_damage: npc_damage!$A$5:$A$109
Name list_npc_kill: npc_kill!$A$5:$A$109
Name list_xp_gain: xp_gain!$A$5:$A$58

Sheet README
A1: MazeRaceBingo - tile balancing workbook
A2: Built against github.com/TiboDeclercq98/mazeracebingo. Estimates expected time to completion (ETC) per tile so you can tune requirements.
B5: 1. How to use it
B6: Step 1 | C6: Open Settings and set your team size, how many players are realistically online at once, how you split them across the three arms, and the event window.
B7: Step 2 | C7: Still on Settings, shape the difficulty curve in section B. That curve is the 'target hours' each tile is scored against - it is what balanced means for your event.
B8: Step 3 | C8: Go to Planner. One row per tile, already sorted START -> Arm 1 -> Arm 2 -> Arm 3 in fog-of-war reveal order, so reading top to bottom is the order players meet them.
B9: Step 4 | C9: Per tile pick a Task type, a Mode, a Target, then up to 24 items from the dropdowns. The dropdowns change to match the task type you picked.
B10: Step 5 | C10: Watch the 'vs target' column. Green = within range, orange = too slow, blue = too easy. Adjust the Target number until it lands where you want.
B11: Step 6 | C11: Check the race forecast on Settings (section D). Slack should be a small positive number - that is a race that finishes with drama rather than one nobody completes.
B12: Step 7 | C12: Copy the JSON column into the taskDefinitions array of your save file.
B15: 2. Colour legend
B16: Blue text on yellow | C16: Input. Type over it. Every rate in this workbook is an editable estimate.
B17: Black text | C17: Formula. Leave alone.
B18: Green text | C18: A link pulling a value from another tab.
B19: Gold row | C19: Key tile (16, 57, 60). All three must be completed before END can be finished.
B20: Orange row | C20: END tile (5).
B21: Pale green row | C21: Skippable tile - a dead end no team is forced to clear.
B24: 3. What the ETC model actually does
B25: The atomic number | C25: Every catalogue entry reduces to r = units of progress per PLAYER-hour. r = (progress per action) x (actions per hour) / (group size). Group size folds raid and mass content in correctly: a 4-man raid at 2 raids/hr costs 2 player-hours per raid, not 0.5.
B26: Mode 'any' | C26: The target is the pooled total. Entries that share a catalogue source are farmed simultaneously, so their rates add. The model takes the FASTEST source group: ETC = target / max(group rate). Seven Zulrah uniques pool into one fat rate; Vorkath and Zulrah do not pool, so the team just farms whichever is quicker.
B27: Mode 'each', random drops | C27: Every listed item must independently reach the target. Items from one source arrive in parallel, so this is a coupon-collector problem. The model uses ETC = sum over items of (solo time / rank), ranking by descending solo time within each source group. For n equally-rare items that reproduces the exact answer H(n)/p; for mixed rarities it is within a few percent of the truth.
B28: Mode 'each', deterministic | C28: Kills, laps, XP and clues are not random, so parallel entries finish together: the model takes the slowest (max). Sequential entries add up (sum). Parallel = Auto means group by source, so different NPCs are sequential by default. Set Parallel = Yes when one activity feeds every entry at once, e.g. Attack, Strength and Defence XP from the same combat method.
B29: Wall-clock | C29: Player-hours / players assigned to that tile + the fixed overhead from Settings. Progress is team-wide, so more players is a straight linear speed-up.
B30: Unlucky column | C30: The 90th-percentile time (change the percentile on Settings). Modelled as a gamma with shape = number of random events needed, so a 1-in-500 single drop has a huge spread and a 200-kill task barely any. Approximate for 'each' mode - treat it as 'this is roughly how bad the tail is', not a precise number.
B31: Race forecast | C31: Fog of war means an arm can only be cleared in order, so an arm's time is the SUM of its forced tiles, and the race is the SLOWEST arm - the team needs all 3 keys and the END path. One bloated tile stalls an entire arm; that is what the 'Longest single tile' line is watching for.
B34: 4. Tab guide
B35: Settings | C35: Global assumptions, the difficulty curve, and the race forecast.
B36: Planner | C36: The working sheet. One row per tile.
B37: Maze | C37: The tile tree read off your maze diagram: parent, arm, depth, role, dead-ends.
B38: npc_kill | C38: Bosses and endgame PvM with kills/hr. Names must match in-game NPC names exactly.
B39: npc_damage | C39: Damage/hr = kills/hr x effective HP, both pulled from npc_kill so you edit once.
B40: xp_gain | C40: One row per skill with an assumed method and XP/hr.
B41: item_drop | C41: The big one. Item, source, drop rate, actions/hr. Source doubles as the pooling key.
B42: agility_lap | C42: The 19 courses the plugin can actually detect. Nothing else will ever fire.
B43: minigame_completion | C43: Minigame plus the chat-message substring the plugin listens for.
B44: clue_completion | C44: The 6 tiers, with acquisition time built into clues/hr.
B45: gp_value | C45: GP/hr by farming method. Only used for ETC - gp_value takes no item list.
B46: Lookup / Calc | C46: Machinery. Do not edit; they rebuild from the tabs above.
B49: 5. Read this before you trust a number
B50: Rates are estimates | C50: Every kills/hr, XP/hr and drop rate here is my best estimate for a competent main account, not gospel. The Confidence column flags how sure I am; anything marked Low, or with VERIFY in the notes, should be checked against the wiki before you build a tile on it. The model is the valuable part - the numbers are a starting point.
...

Sheet Settings
A1: Settings - global assumptions
A2: Everything on this sheet drives the ETC model. Blue cells are yours to change.
A4: A. Team & schedule | E4: JSON field names (do not edit)
A5: Roster size (players on the team) | B5: 1 | C5: Reference only. | E5: Task type | F5: Singular field | G5: Plural field
A6: Players online & on-task at once | B6: 1 | C6: Realistic concurrent contributors across the whole team. | E6: npc_kill | F6: npc | G6: npcs
A7: Players working Arm 1 (blue) | B7: 1 | C7: Default players per tile on this arm. The three should add up to the line above. | E7: npc_damage | F7: npc | G7: npcs
A8: Players working Arm 2 (green) | B8: 1 | C8: One team of 5 clears arms one at a time. | E8: xp_gain | F8: skill | G8: skills
A9: Players working Arm 3 (orange) | B9: 1 | C9: Arm 3 holds the END tile. | E9: item_drop | F9: item | G9: items
A10: Rate multiplier (1.00 = catalogue rates) | B10: 1 | C10: 0.7 = casual / mid accounts, 1.0 = competent mains, 1.3 = efficient endgame team. | E10: agility_lap | F10: course | G10: courses
A11: Fixed overhead per tile (minutes) | B11: 12 | C11: Travel, banking, gearing, and working out what the tile even wants. | E11: minigame_completion | F11: minigame | G11: minigame
A12: 'Unlucky' percentile | B12: 0.9 | C12: 0.90 = the time 90% of runs come in under. Drives the Unlucky column. | E12: clue_completion | F12: tier | G12: tiers
E13: gp_value | F13: - | G13: -
A15: B. Difficulty target curve (what you are balancing TOWARD)
A16: Base target - WALL-CLOCK hours at depth 0 | B16: 0.42 | C16: Target time for a tile sitting right next to START.
A17: Target coefficient on depth^exponent | B17: 0.0104 | C17: Target = (base + slope * depth^exp) * role multiplier.
A18: Depth curve exponent | B18: 1.65 | C18: 1 = linear ramp. >1 = back-loaded.
A19: Role multiplier - KEY tile | B19: 1.7 | C19: Tiles 16, 57 and 60 - one in each arm.
A20: Role multiplier - END tile | B20: 2.2 | C20: Tile 5. Needs all 3 keys first.
A21: Role multiplier - Skippable tile | B21: 0.55 | C21: The 10 dead-end tiles nobody is forced to do. Keep them cheap and tempting.
A24: C. Event window
A25: Event length (days) | B25: 30
A26: Playable hours per day | B26: 5 | C26: Per player, realistically.
A27: Total event window (hours) | B27: =cfg_days*cfg_hoursday -> 150
A30: D. Race forecast - fog of war means each arm must be cleared IN ORDER
B31: Arm 1 (blue) | C31: Arm 2 (green) | D31: Arm 3 (orange) | E31: All arms
A32: Tiles on the arm | B32: =COUNTIF(Planner!$B$5:$B$85,"Arm 1") -> 22 | C32: =COUNTIF(Planner!$B$5:$B$85,"Arm 2") -> 27 | D32: =COUNTIF(Planner!$B$5:$B$85,"Arm 3") -> 31 | E32: =COUNTA(Planner!$A$5:$A$85) -> 81
A33: Tiles with a task set | B33: =COUNTIFS(Planner!$B$5:$B$85,"Arm 1",Planner!$F$5:$F$85,"<>") -> 22 | C33: =COUNTIFS(Planner!$B$5:$B$85,"Arm 2",Planner!$F$5:$F$85,"<>") -> 27 | D33: =COUNTIFS(Planner!$B$5:$B$85,"Arm 3",Planner!$F$5:$F$85,"<>") -> 31 | E33: =COUNTIF(Planner!$F$5:$F$85,"<>") -> 81
A34: Forced tiles (must be done) | B34: =COUNTIFS(Planner!$B$5:$B$85,"Arm 1",Planner!$D$5:$D$85,"<>Skippable") -> 19 | C34: =COUNTIFS(Planner!$B$5:$B$85,"Arm 2",Planner!$D$5:$D$85,"<>Skippable") -> 25 | D34: =COUNTIFS(Planner!$B$5:$B$85,"Arm 3",Planner!$D$5:$D$85,"<>Skippable") -> 26 | E34: =COUNTIF(Planner!$D$5:$D$85,"<>Skippable") -> 71
A35: Player-hours, forced tiles | B35: =SUMIFS(Planner!$AL$5:$AL$85,Planner!$B$5:$B$85,"Arm 1",Planner!$D$5:$D$85,"<>Skippable") -> 169.41486 | C35: =SUMIFS(Planner!$AL$5:$AL$85,Planner!$B$5:$B$85,"Arm 2",Planner!$D$5:$D$85,"<>Skippable") -> 214.16877 | D35: =SUMIFS(Planner!$AL$5:$AL$85,Planner!$B$5:$B$85,"Arm 3",Planner!$D$5:$D$85,"<>Skippable") -> 247.12755 | E35: =SUMIFS(Planner!$AL$5:$AL$85,Planner!$D$5:$D$85,"<>Skippable") -> 632.51841
A36: Wall-clock hours, forced tiles | B36: =SUMIFS(Planner!$AM$5:$AM$85,Planner!$B$5:$B$85,"Arm 1",Planner!$D$5:$D$85,"<>Skippable") -> 173.21486 | C36: =SUMIFS(Planner!$AM$5:$AM$85,Planner!$B$5:$B$85,"Arm 2",Planner!$D$5:$D$85,"<>Skippable") -> 219.16877 | D36: =SUMIFS(Planner!$AM$5:$AM$85,Planner!$B$5:$B$85,"Arm 3",Planner!$D$5:$D$85,"<>Skippable") -> 252.32755 | E36: =SUM(B36:D36) -> 644.71118
A37: Wall-clock, all tiles incl. skippable | B37: =SUMIFS(Planner!$AM$5:$AM$85,Planner!$B$5:$B$85,"Arm 1") -> 229.27996 | C37: =SUMIFS(Planner!$AM$5:$AM$85,Planner!$B$5:$B$85,"Arm 2") -> 330.15701 | D37: =SUMIFS(Planner!$AM$5:$AM$85,Planner!$B$5:$B$85,"Arm 3") -> 275.72788 | E37: =SUM(B37:D37) -> 835.16484
A39: PREDICTED RACE LENGTH - one team (hours) | B39: =E36 -> 644.71118 | C39: ONE team of 5 cannot be in three arms at once, and a key sits in EVERY arm (16 = Arm 2, 57 = Arm 3, 60 = Arm 1), so it is the SUM of all arms. If you run 3 teams racing in parallel instead, use the slowest arm: =MAX(B36:D36).
A40: Event window (hours) | B40: =cfg_window -> 150 | C40: From section C above.
A41: Slack (window - race length) | B41: =B40-B39 -> -494.71118 | C41: Negative = nobody finishes. A small positive number = a tight, exciting race.
A42: Longest single tile (wall-clock hrs) | B42: =MAX(Planner!$AM$5:$AM$85) -> 100.2 | C42: Watch for one tile that stalls the whole run.
A43: Tiles over 2x their target | B43: =COUNTIF(Planner!$AM$5:$AM$85,">2") -> 74 | C43: Rebalance these first.
A44: Tiles under 0.5x their target | B44: =COUNTIF(Planner!$AM$5:$AM$85,"<0.5") -> 0 | C44: Free tiles - consider making them meaner.
A45: (parallel variant) slowest arm only | B45: =MAX(B36,C36,D36) -> 252.32755 | C45: Only meaningful if you field one squad per arm.

Sheet Planner
A1: Planner - one row per maze tile
A2: Blue cells are inputs. Choose a task type first: the 24 item dropdowns then offer only entries from that type's tab. Everything right of the item slots is calculated.
A3: Mode 'any' = the target is the TOTAL across all listed entries. Mode 'each' = EVERY listed entry must independently reach the target (the tile requirement becomes items x target). Parallel: Auto = group by catalogue source | Yes = all entries progress at once (e.g. Atk/Str/Def from one combat method) | No = force one at a time.
A4: Tile | B4: Arm | C4: Depth | D4: Role | E4: Chest? | F4: Task type | G4: Mode | H4: Target | I4: Parallel | J4: Rate mult | K4: Players | L4: Item 1 | M4: Item 2 | N4: Item 3 | O4: Item 4 | P4: Item 5 | Q4: Item 6 | R4: Item 7 | S4: Item 8 | T4: Item 9 | U4: Item 10 | V4: Item 11 | W4: Item 12 | X4: Item 13 | Y4: Item 14 | Z4: Item 15 | AA4: Item 16 | AB4: Item 17 | AC4: Item 18 | AD4: Item 19 | AE4: Item 20 | AF4: Item 21 | AG4: Item 22 | AH4: Item 23 | AI4: Item 24 | AJ4: # items | AK4: Units req. | AL4: Player-hours | AM4: Wall-clock hrs | AN4: Wall-clock | AO4: Unlucky hrs | AP4: Target hrs | AQ4: vs target | AR4: Warnings | AS4: Description | AT4: JSON (paste into taskDefinitions)
A5: 77 | B5: =IFERROR(INDEX(Maze!$C$5:$C$85,MATCH($A5,Maze!$A$5:$A$85,0)),"") -> START | C5: =IFERROR(INDEX(Maze!$D$5:$D$85,MATCH($A5,Maze!$A$5:$A$85,0)),"") -> 0 | D5: =IFERROR(INDEX(Maze!$E$5:$E$85,MATCH($A5,Maze!$A$5:$A$85,0)),"") -> START | E5: =IFERROR(INDEX(Maze!$G$5:$G$85,MATCH($A5,Maze!$A$5:$A$85,0)),"") -> No | F5: agility_lap | H5: 150 | L5: Draynor | AJ5: {=SUMPRODUCT(($L5:$AI5<>"")*1)} -> 1 | AK5: =IF($F5="","",IF($G5="each",$AJ5*$H5,$H5)) -> 150 | AL5: =IF($F5="","",IFERROR((IF($G5="each",IF($I5="No",SUM(Calc!$BZ5:$CW5),IF($F5="item_drop",SUM(Calc!$DX5:$EU5),IF($I5="Yes",MAX(Calc!$BZ5:$CW5),SUM(Calc!$BZ5:$CW5)))),$H5/MAX(Calc!$BA5:$BX5)))/IF($J5="",cfg_ratemult,$J5),"")) -> 1.8072289 | AM5: =IF($AL5="","",$AL5/MAX(0.1,IF($K5="",IF($B5="Arm 1",cfg_arm1,IF($B5="Arm 2",cfg_arm2,IF($B5="Arm 3",cfg_arm3,cfg_concurrent))),$K5))+cfg_overhead/60) -> 2.0072289 | AN5: =IF($AM5="","",INT($AM5/24)&"d "&TEXT(MOD($AM5,24),"0.0")&"h") -> 0d 02h | AO5: =IF($AM5="","",$AL5*IFERROR(GAMMAINV(cfg_pct,MAX(1,IF($F5="item_drop",IF($G5="each",$AJ5*$H5,$H5),1000)),1/MAX(1,IF($F5="item_drop",IF($G5="each",$AJ5*$H5,$H5),1000))),1)/MAX(0.1,IF($K5="",IF($B5="Arm 1",cfg_arm1,IF($B5="Arm 2",cfg_arm2,IF($B5="Arm 3",cfg_arm3,cfg_concurrent))),$K5))+cfg_overhead/60) -> 2.0808451 | AP5: =(cfg_base+cfg_slope*$C5^cfg_exp)*IF($D5="KEY",cfg_mkey,IF($D5="END",cfg_mend,IF($D5="Skippable",cfg_mskip,1))) -> 0.42 | AQ5: =IF(OR($AM5="",$AP5=0),"",$AM5/$AP5) -> 4.7791165 | AR5: {=IF($F5="","- no task set -",_xlfn.TEXTJOIN(" | ",TRUE,IF(AND($F5<>"gp_value",$AJ5=0),"no items selected",""),IF(AND($F5="gp_value",$AJ5=0),"pick a farming method so the ETC can be estimated",""),IF(AND($F5="gp_value",$AJ5>1),"gp_value takes no item list - one method is enough",""),IF(AND($F5="minigame_completion",$AJ5>1),"only 1 minigame per tile",""),IF(OR($H5="",$H5<=0),"target missing",""),IF(SUMPRODUCT(($L5:$AE5<>"")*(Calc!$C5:$Z5=0))>0,"unknown entry - not in catalogue",""),IF(AND($G5="each",$AJ5=1),"each with 1 entry = same as any",""),IF($AL5="","ETC not computable","")))} -> #N/A | AS5: Wait this isn't Leagues? | AT5: =IF($F5="","","{"&CHAR(34)&"tileId"&CHAR(34)&":"&$A5&","&CHAR(34)&"taskType"&CHAR(34)&":"&CHAR(34)&$F5&CHAR(34)&","&CHAR(34)&"taskConfig"&CHAR(34)&":{"&IF($F5="gp_value","",IF($F5="minigame_completion",CHAR(34)&"minigame"&CHAR(34)&":"&CHAR(34)&$L5&CHAR(34)&","&CHAR(34)&"message"&CHAR(34)&":"&CHAR(34)&IFERROR(INDEX(minigame_completion!$J$5:$J$47,MATCH($L5,minigame_completion!$A$5:$A$47,0)),"")&CHAR(34)&",",IF($AJ5=1,CHAR(34)&INDEX(Settings!$F$6:$F$13,MATCH($F5,Settings!$E$6:$E$13,0))&CHAR(34)&":"&Calc!$EW5&",",CHAR(34)&INDEX(Settings!$G$6:$G$13,MATCH($F5,Settings!$E$6:$E$13,0))&CHAR(34)&":["&_xlfn.TEXTJOIN(",",TRUE,Calc!$EW5:$FT5)&"],")))&CHAR(34)&"target"&CHAR(34)&":"&$H5&IF($G5="each",","&CHAR(34)&"mode"&CHAR(34)&":"&CHAR(34)&"each"&CHAR(34),"")&"}}") -> {"tileId":77,"taskType":"agility_lap","taskConfig":{"course":"Draynor","target":150}}
A6: 78 | B6: =IFERROR(INDEX(Maze!$C$5:$C$85,MATCH($A6,Maze!$A$5:$A$85,0)),"") -> Arm 1 | C6: =IFERROR(INDEX(Maze!$D$5:$D$85,MATCH($A6,Maze!$A$5:$A$85,0)),"") -> 1 | D6: =IFERROR(INDEX(Maze!$E$5:$E$85,MATCH($A6,Maze!$A$5:$A$85,0)),"") -> Forced | E6: =IFERROR(INDEX(Maze!$G$5:$G$85,MATCH($A6,Maze!$A$5:$A$85,0)),"") -> No | F6: minigame_completion | H6: 100 | L6: Tempoross | AJ6: {=SUMPRODUCT(($L6:$AI6<>"")*1)} -> 1 | AK6: =IF($F6="","",IF($G6="each",$AJ6*$H6,$H6)) -> 100 | AL6: =IF($F6="","",IFERROR((IF($G6="each",IF($I6="No",SUM(Calc!$BZ6:$CW6),IF($F6="item_drop",SUM(Calc!$DX6:$EU6),IF($I6="Yes",MAX(Calc!$BZ6:$CW6),SUM(Calc!$BZ6:$CW6)))),$H6/MAX(Calc!$BA6:$BX6)))/IF($J6="",cfg_ratemult,$J6),"")) -> 11.111111 | AM6: =IF($AL6="","",$AL6/MAX(0.1,IF($K6="",IF($B6="Arm 1",cfg_arm1,IF($B6="Arm 2",cfg_arm2,IF($B6="Arm 3",cfg_arm3,cfg_concurrent))),$K6))+cfg_overhead/60) -> 11.311111 | AN6: =IF($AM6="","",INT($AM6/24)&"d "&TEXT(MOD($AM6,24),"0.0")&"h") -> 0d 11h | AO6: =IF($AM6="","",$AL6*IFERROR(GAMMAINV(cfg_pct,MAX(1,IF($F6="item_drop",IF($G6="each",$AJ6*$H6,$H6),1000)),1/MAX(1,IF($F6="item_drop",IF($G6="each",$AJ6*$H6,$H6),1000))),1)/MAX(0.1,IF($K6="",IF($B6="Arm 1",cfg_arm1,IF($B6="Arm 2",cfg_arm2,IF($B6="Arm 3",cfg_arm3,cfg_concurrent))),$K6))+cfg_overhead/60) -> 11.763715 | AP6: =(cfg_base+cfg_slope*$C6^cfg_exp)*IF($D6="KEY",cfg_mkey,IF($D6="END",cfg_mend,IF($D6="Skippable",cfg_mskip,1))) -> 0.4304 | AQ6: =IF(OR($AM6="",$AP6=0),"",$AM6/$AP6) -> 26.280463 | AR6: =IF($F6="","- no task set -",_xlfn.TEXTJOIN(" | ",TRUE,IF(AND($F6<>"gp_value",$AJ6=0),"no items selected",""),IF(AND($F6="gp_value",$AJ6=0),"pick a farming method so the ETC can be estimated",""),IF(AND($F6="gp_value",$AJ6>1),"gp_value takes no item list - one method is enough",""),IF(AND($F6="minigame_completion",$AJ6>1),"only 1 minigame per tile",""),IF(OR($H6="",$H6<=0),"target missing",""),IF(SUMPRODUCT(($L6:$AE6<>"")*(Calc!$C6:$Z6=0))>0,"unknown entry - not in catalogue",""),IF(AND($G6="each",$AJ6=1),"each with 1 entry = same as any",""),IF($AL6="","ETC not computable",""))) -> #N/A | AS6: Here fishy fishies! | AT6: =IF($F6="","","{"&CHAR(34)&"tileId"&CHAR(34)&":"&$A6&","&CHAR(34)&"taskType"&CHAR(34)&":"&CHAR(34)&$F6&CHAR(34)&","&CHAR(34)&"taskConfig"&CHAR(34)&":{"&IF($F6="gp_value","",IF($F6="minigame_completion",CHAR(34)&"minigame"&CHAR(34)&":"&CHAR(34)&$L6&CHAR(34)&","&CHAR(34)&"message"&CHAR(34)&":"&CHAR(34)&IFERROR(INDEX(minigame_completion!$J$5:$J$47,MATCH($L6,minigame_completion!$A$5:$A$47,0)),"")&CHAR(34)&",",IF($AJ6=1,CHAR(34)&INDEX(Settings!$F$6:$F$13,MATCH($F6,Settings!$E$6:$E$13,0))&CHAR(34)&":"&Calc!$EW6&",",CHAR(34)&INDEX(Settings!$G$6:$G$13,MATCH($F6,Settings!$E$6:$E$13,0))&CHAR(34)&":["&_xlfn.TEXTJOIN(",",TRUE,Calc!$EW6:$FT6)&"],")))&CHAR(34)&"target"&CHAR(34)&":"&$H6&IF($G6="each",","&CHAR(34)&"mode"&CHAR(34)&":"&CHAR(34)&"each"&CHAR(34),"")&"}}") -> {"tileId":78,"taskType":"minigame_completion","taskConfig":{"minigame":"Tempoross","message":"Tempoross kill count is","target":100}}
A7: 69 | B7: =IFERROR(INDEX(Maze!$C$5:$C$85,MATCH($A7,Maze!$A$5:$A$85,0)),"") -> Arm 1 | C7: =IFERROR(INDEX(Maze!$D$5:$D$85,MATCH($A7,Maze!$A$5:$A$85,0)),"") -> 2 | D7: =IFERROR(INDEX(Maze!$E$5:$E$85,MATCH($A7,Maze!$A$5:$A$85,0)),"") -> Forced | E7: =IFERROR(INDEX(Maze!$G$5:$G$85,MATCH($A7,Maze!$A$5:$A$85,0)),"") -> No | F7: clue_completion | H7: 50 | L7: beginner | AJ7: {=SUMPRODUCT(($L7:$AI7<>"")*1)} -> 1 | AK7: =IF($F7="","",IF($G7="each",$AJ7*$H7,$H7)) -> 50 | AL7: =IF($F7="","",IFERROR((IF($G7="each",IF($I7="No",SUM(Calc!$BZ7:$CW7),IF($F7="item_drop",SUM(Calc!$DX7:$EU7),IF($I7="Yes",MAX(Calc!$BZ7:$CW7),SUM(Calc!$BZ7:$CW7)))),$H7/MAX(Calc!$BA7:$BX7)))/IF($J7="",cfg_ratemult,$J7),"")) -> 2.5 | AM7: =IF($AL7="","",$AL7/MAX(0.1,IF($K7="",IF($B7="Arm 1",cfg_arm1,IF($B7="Arm 2",cfg_arm2,IF($B7="Arm 3",cfg_arm3,cfg_concurrent))),$K7))+cfg_overhead/60) -> 2.7 | AN7: =IF($AM7="","",INT($AM7/24)&"d "&TEXT(MOD($AM7,24),"0.0")&"h") -> 0d 03h | AO7: =IF($AM7="","",$AL7*IFERROR(GAMMAINV(cfg_pct,MAX(1,IF($F7="item_drop",IF($G7="each",$AJ7*$H7,$H7),1000)),1/MAX(1,IF($F7="item_drop",IF($G7="each",$AJ7*$H7,$H7),1000))),1)/MAX(0.1,IF($K7="",IF($B7="Arm 1",cfg_arm1,IF($B7="Arm 2",cfg_arm2,IF($B7="Arm 3",cfg_arm3,cfg_concurrent))),$K7))+cfg_overhead/60) -> 2.8018358 | AP7: =(cfg_base+cfg_slope*$C7^cfg_exp)*IF($D7="KEY",cfg_mkey,IF($D7="END",cfg_mend,IF($D7="Skippable",cfg_mskip,1))) -> 0.4526387 | AQ7: =IF(OR($AM7="",$AP7=0),"",$AM7/$AP7) -> 5.9650225 | AR7: =IF($F7="","- no task set -",_xlfn.TEXTJOIN(" | ",TRUE,IF(AND($F7<>"gp_value",$AJ7=0),"no items selected",""),IF(AND($F7="gp_value",$AJ7=0),"pick a farming method so the ETC can be estimated",""),IF(AND($F7="gp_value",$AJ7>1),"gp_value takes no item list - one method is enough",""),IF(AND($F7="minigame_completion",$AJ7>1),"only 1 minigame per tile",""),IF(OR($H7="",$H7<=0),"target missing",""),IF(SUMPRODUCT(($L7:$AE7<>"")*(Calc!$C7:$Z7=0))>0,"unknown entry - not in catalogue",""),IF(AND($G7="each",$AJ7=1),"each with 1 entry = same as any",""),IF($AL7="","ETC not computable",""))) -> #N/A | AS7: In the beninging | AT7: =IF($F7="","","{"&CHAR(34)&"tileId"&CHAR(34)&":"&$A7&","&CHAR(34)&"taskType"&CHAR(34)&":"&CHAR(34)&$F7&CHAR(34)&","&CHAR(34)&"taskConfig"&CHAR(34)&":{"&IF($F7="gp_value","",IF($F7="minigame_completion",CHAR(34)&"minigame"&CHAR(34)&":"&CHAR(34)&$L7&CHAR(34)&","&CHAR(34)&"message"&CHAR(34)&":"&CHAR(34)&IFERROR(INDEX(minigame_completion!$J$5:$J$47,MATCH($L7,minigame_completion!$A$5:$A$47,0)),"")&CHAR(34)&",",IF($AJ7=1,CHAR(34)&INDEX(Settings!$F$6:$F$13,MATCH($F7,Settings!$E$6:$E$13,0))&CHAR(34)&":"&Calc!$EW7&",",CHAR(34)&INDEX(Settings!$G$6:$G$13,MATCH($F7,Settings!$E$6:$E$13,0))&CHAR(34)&":["&_xlfn.TEXTJOIN(",",TRUE,Calc!$EW7:$FT7)&"],")))&CHAR(34)&"target"&CHAR(34)&":"&$H7&IF($G7="each",","&CHAR(34)&"mode"&CHAR(34)&":"&CHAR(34)&"each"&CHAR(34),"")&"}}") -> {"tileId":69,"taskType":"clue_completion","taskConfig":{"tier":"beginner","target":50}}
A8: 70 | B8: =IFERROR(INDEX(Maze!$C$5:$C$85,MATCH($A8,Maze!$A$5:$A$85,0)),"") -> Arm 1 | C8: =IFERROR(INDEX(Maze!$D$5:$D$85,MATCH($A8,Maze!$A$5:$A$85,0)),"") -> 3 | D8: =IFERROR(INDEX(Maze!$E$5:$E$85,MATCH($A8,Maze!$A$5:$A$85,0)),"") -> Forced | E8: =IFERROR(INDEX(Maze!$G$5:$G$85,MATCH($A8,Maze!$A$5:$A$85,0)),"") -> No | F8: npc_kill | H8: 50 | L8: Obor | AJ8: {=SUMPRODUCT(($L8:$AI8<>"")*1)} -> 1 | AK8: =IF($F8="","",IF($G8="each",$AJ8*$H8,$H8)) -> 50 | AL8: =IF($F8="","",IFERROR((IF($G8="each",IF($I8="No",SUM(Calc!$BZ8:$CW8),IF($F8="item_drop",SUM(Calc!$DX8:$EU8),IF($I8="Yes",MAX(Calc!$BZ8:$CW8),SUM(Calc!$BZ8:$CW8)))),$H8/MAX(Calc!$BA8:$BX8)))/IF($J8="",cfg_ratemult,$J8),"")) -> 1.6666667 | AM8: =IF($AL8="","",$AL8/MAX(0.1,IF($K8="",IF($B8="Arm 1",cfg_arm1,IF($B8="Arm 2",cfg_arm2,IF($B8="Arm 3",cfg_arm3,cfg_concurrent))),$K8))+cfg_overhead/60) -> 1.8666667 | AN8: =IF($AM8="","",INT($AM8/24)&"d "&TEXT(MOD($AM8,24),"0.0")&"h") -> 0d 02h | AO8: =IF($AM8="","",$AL8*IFERROR(GAMMAINV(cfg_pct,MAX(1,IF($F8="item_drop",IF($G8="each",$AJ8*$H8,$H8),1000)),1/MAX(1,IF($F8="item_drop",IF($G8="each",$AJ8*$H8,$H8),1000))),1)/MAX(0.1,IF($K8="",IF($B8="Arm 1",cfg_arm1,IF($B8="Arm 2",cfg_arm2,IF($B8="Arm 3",cfg_arm3,cfg_concurrent))),$K8))+cfg_overhead/60) -> 1.9345572 | AP8: =(cfg_base+cfg_slope*$C8^cfg_exp)*IF($D8="KEY",cfg_mkey,IF($D8="END",cfg_mend,IF($D8="Skippable",cfg_mskip,1))) -> 0.48372112 | AQ8: =IF(OR($AM8="",$AP8=0),"",$AM8/$AP8) -> 3.8589728 | AR8: =IF($F8="","- no task set -",_xlfn.TEXTJOIN(" | ",TRUE,IF(AND($F8<>"gp_value",$AJ8=0),"no items selected",""),IF(AND($F8="gp_value",$AJ8=0),"pick a farming method so the ETC can be estimated",""),IF(AND($F8="gp_value",$AJ8>1),"gp_value takes no item list - one method is enough",""),IF(AND($F8="minigame_completion",$AJ8>1),"only 1 minigame per tile",""),IF(OR($H8="",$H8<=0),"target missing",""),IF(SUMPRODUCT(($L8:$AE8<>"")*(Calc!$C8:$Z8=0))>0,"unknown entry - not in catalogue",""),IF(AND($G8="each",$AJ8=1),"each with 1 entry = same as any",""),IF($AL8="","ETC not computable",""))) -> #N/A | AS8: You're gonna need some keys | AT8: =IF($F8="","","{"&CHAR(34)&"tileId"&CHAR(34)&":"&$A8&","&CHAR(34)&"taskType"&CHAR(34)&":"&CHAR(34)&$F8&CHAR(34)&","&CHAR(34)&"taskConfig"&CHAR(34)&":{"&IF($F8="gp_value","",IF($F8="minigame_completion",CHAR(34)&"minigame"&CHAR(34)&":"&CHAR(34)&$L8&CHAR(34)&","&CHAR(34)&"message"&CHAR(34)&":"&CHAR(34)&IFERROR(INDEX(minigame_completion!$J$5:$J$47,MATCH($L8,minigame_completion!$A$5:$A$47,0)),"")&CHAR(34)&",",IF($AJ8=1,CHAR(34)&INDEX(Settings!$F$6:$F$13,MATCH($F8,Settings!$E$6:$E$13,0))&CHAR(34)&":"&Calc!$EW8&",",CHAR(34)&INDEX(Settings!$G$6:$G$13,MATCH($F8,Settings!$E$6:$E$13,0))&CHAR(34)&":["&_xlfn.TEXTJOIN(",",TRUE,Calc!$EW8:$FT8)&"],")))&CHAR(34)&"target"&CHAR(34)&":"&$H8&IF($G8="each",","&CHAR(34)&"mode"&CHAR(34)&":"&CHAR(34)&"each"&CHAR(34),"")&"}}") -> {"tileId":70,"taskType":"npc_kill","taskConfig":{"npc":"Obor","target":50}}
A9: 71 | B9: =IFERROR(INDEX(Maze!$C$5:$C$85,MATCH($A9,Maze!$A$5:$A$85,0)),"") -> Arm 1 | C9: =IFERROR(INDEX(Maze!$D$5:$D$85,MATCH($A9,Maze!$A$5:$A$85,0)),"") -> 4 | D9: =IFERROR(INDEX(Maze!$E$5:$E$85,MATCH($A9,Maze!$A$5:$A$85,0)),"") -> Forced | E9: =IFERROR(INDEX(Maze!$G$5:$G$85,MATCH($A9,Maze!$A$5:$A$85,0)),"") -> No | F9: npc_kill | H9: 50 | L9: Amoxliatl | AJ9: {=SUMPRODUCT(($L9:$AI9<>"")*1)} -> 1 | AK9: =IF($F9="","",IF($G9="each",$AJ9*$H9,$H9)) -> 50 | AL9: =IF($F9="","",IFERROR((IF($G9="each",IF($I9="No",SUM(Calc!$BZ9:$CW9),IF($F9="item_drop",SUM(Calc!$DX9:$EU9),IF($I9="Yes",MAX(Calc!$BZ9:$CW9),SUM(Calc!$BZ9:$CW9)))),$H9/MAX(Calc!$BA9:$BX9)))/IF($J9="",cfg_ratemult,$J9),"")) -> 0.71428571 | AM9: =IF($AL9="","",$AL9/MAX(0.1,IF($K9="",IF($B9="Arm 1",cfg_arm1,IF($B9="Arm 2",cfg_arm2,IF($B9="Arm 3",cfg_arm3,cfg_concurrent))),$K9))+cfg_overhead/60) -> 0.91428571 | AN9: =IF($AM9="","",INT($AM9/24)&"d "&TEXT(MOD($AM9,24),"0.0")&"h") -> 0d 01h | AO9: =IF($AM9="","",$AL9*IFERROR(GAMMAINV(cfg_pct,MAX(1,IF($F9="item_drop",IF($G9="each",$AJ9*$H9,$H9),1000)),1/MAX(1,IF($F9="item_drop",IF($G9="each",$AJ9*$H9,$H9),1000))),1)/MAX(0.1,IF($K9="",IF($B9="Arm 1",cfg_arm1,IF($B9="Arm 2",cfg_arm2,IF($B9="Arm 3",cfg_arm3,cfg_concurrent))),$K9))+cfg_overhead/60) -> 0.94338165 | AP9: =(cfg_base+cfg_slope*$C9^cfg_exp)*IF($D9="KEY",cfg_mkey,IF($D9="END",cfg_mend,IF($D9="Skippable",cfg_mskip,1))) -> 0.52243122 | AQ9: =IF(OR($AM9="",$AP9=0),"",$AM9/$AP9) -> 1.7500595 | AR9: =IF($F9="","- no task set -",_xlfn.TEXTJOIN(" | ",TRUE,IF(AND($F9<>"gp_value",$AJ9=0),"no items selected",""),IF(AND($F9="gp_value",$AJ9=0),"pick a farming method so the ETC can be estimated",""),IF(AND($F9="gp_value",$AJ9>1),"gp_value takes no item list - one method is enough",""),IF(AND($F9="minigame_completion",$AJ9>1),"only 1 minigame per tile",""),IF(OR($H9="",$H9<=0),"target missing",""),IF(SUMPRODUCT(($L9:$AE9<>"")*(Calc!$C9:$Z9=0))>0,"unknown entry - not in catalogue",""),IF(AND($G9="each",$AJ9=1),"each with 1 entry = same as any",""),IF($AL9="","ETC not computable",""))) -> #N/A | AS9: I think that's a Pokémon | AT9: =IF($F9="","","{"&CHAR(34)&"tileId"&CHAR(34)&":"&$A9&","&CHAR(34)&"taskType"&CHAR(34)&":"&CHAR(34)&$F9&CHAR(34)&","&CHAR(34)&"taskConfig"&CHAR(34)&":{"&IF($F9="gp_value","",IF($F9="minigame_completion",CHAR(34)&"minigame"&CHAR(34)&":"&CHAR(34)&$L9&CHAR(34)&","&CHAR(34)&"message"&CHAR(34)&":"&CHAR(34)&IFERROR(INDEX(minigame_completion!$J$5:$J$47,MATCH($L9,minigame_completion!$A$5:$A$47,0)),"")&CHAR(34)&",",IF($AJ9=1,CHAR(34)&INDEX(Settings!$F$6:$F$13,MATCH($F9,Settings!$E$6:$E$13,0))&CHAR(34)&":"&Calc!$EW9&",",CHAR(34)&INDEX(Settings!$G$6:$G$13,MATCH($F9,Settings!$E$6:$E$13,0))&CHAR(34)&":["&_xlfn.TEXTJOIN(",",TRUE,Calc!$EW9:$FT9)&"],")))&CHAR(34)&"target"&CHAR(34)&":"&$H9&IF($G9="each",","&CHAR(34)&"mode"&CHAR(34)&":"&CHAR(34)&"each"&CHAR(34),"")&"}}") -> {"tileId":71,"taskType":"npc_kill","taskConfig":{"npc":"Amoxliatl","target":50}}
A10: 80 | B10: =IFERROR(INDEX(Maze!$C$5:$C$85,MATCH($A10,Maze!$A$5:$A$85,0)),"") -> Arm 1 | C10: =IFERROR(INDEX(Maze!$D$5:$D$85,MATCH($A10,Maze!$A$5:$A$85,0)),"") -> 5 | D10: =IFERROR(INDEX(Maze!$E$5:$E$85,MATCH($A10,Maze!$A$5:$A$85,0)),"") -> Forced | E10: =IFERROR(INDEX(Maze!$G$5:$G$85,MATCH($A10,Maze!$A$5:$A$85,0)),"") -> No | F10: item_drop | H10: 1 | L10: Sarachnis cudgel | AJ10: {=SUMPRODUCT(($L10:$AI10<>"")*1)} -> 1 | AK10: =IF($F10="","",IF($G10="each",$AJ10*$H10,$H10)) -> 1 | AL10: =IF($F10="","",IFERROR((IF($G10="each",IF($I10="No",SUM(Calc!$BZ10:$CW10),IF($F10="item_drop",SUM(Calc!$DX10:$EU10),IF($I10="Yes",MAX(Calc!$BZ10:$CW10),SUM(Calc!$BZ10:$CW10)))),$H10/MAX(Calc!$BA10:$BX10)))/IF($J10="",cfg_ratemult,$J10),"")) -> 6.4 | AM10: =IF($AL10="","",$AL10/MAX(0.1,IF($K10="",IF($B10="Arm 1",cfg_arm1,IF($B10="Arm 2",cfg_arm2,IF($B10="Arm 3",cfg_arm3,cfg_concurrent))),$K10))+cfg_overhead/60) -> 6.6 | AN10: =IF($AM10="","",INT($AM10/24)&"d "&TEXT(MOD($AM10,24),"0.0")&"h") -> 0d 07h | AO10: =IF($AM10="","",$AL10*IFERROR(GAMMAINV(cfg_pct,MAX(1,IF($F10="item_drop",IF($G10="each",$AJ10*$H10,$H10),1000)),1/MAX(1,IF($F10="item_drop",IF($G10="each",$AJ10*$H10,$H10),1000))),1)/MAX(0.1,IF($K10="",IF($B10="Arm 1",cfg_arm1,IF($B10="Arm 2",cfg_arm2,IF($B10="Arm 3",cfg_arm3,cfg_concurrent))),$K10))+cfg_overhead/60) -> 14.936545 | AP10: =(cfg_base+cfg_slope*$C10^cfg_exp)*IF($D10="KEY",cfg_mkey,IF($D10="END",cfg_mend,IF($D10="Skippable",cfg_mskip,1))) -> 0.56802458 | AQ10: =IF(OR($AM10="",$AP10=0),"",$AM10/$AP10) -> 11.619215 | AR10: =IF($F10="","- no task set -",_xlfn.TEXTJOIN(" | ",TRUE,IF(AND($F10<>"gp_value",$AJ10=0),"no items selected",""),IF(AND($F10="gp_value",$AJ10=0),"pick a farming method so the ETC can be estimated",""),IF(AND($F10="gp_value",$AJ10>1),"gp_value takes no item list - one method is enough",""),IF(AND($F10="minigame_completion",$AJ10>1),"only 1 minigame per tile",""),IF(OR($H10="",$H10<=0),"target missing",""),IF(SUMPRODUCT(($L10:$AE10<>"")*(Calc!$C10:$Z10=0))>0,"unknown entry - not in catalogue",""),IF(AND($G10="each",$AJ10=1),"each with 1 entry = same as any",""),IF($AL10="","ETC not computable",""))) -> #N/A | AS10: Bonk! | AT10: =IF($F10="","","{"&CHAR(34)&"tileId"&CHAR(34)&":"&$A10&","&CHAR(34)&"taskType"&CHAR(34)&":"&CHAR(34)&$F10&CHAR(34)&","&CHAR(34)&"taskConfig"&CHAR(34)&":{"&IF($F10="gp_value","",IF($F10="minigame_completion",CHAR(34)&"minigame"&CHAR(34)&":"&CHAR(34)&$L10&CHAR(34)&","&CHAR(34)&"message"&CHAR(34)&":"&CHAR(34)&IFERROR(INDEX(minigame_completion!$J$5:$J$47,MATCH($L10,minigame_completion!$A$5:$A$47,0)),"")&CHAR(34)&",",IF($AJ10=1,CHAR(34)&INDEX(Settings!$F$6:$F$13,MATCH($F10,Settings!$E$6:$E$13,0))&CHAR(34)&":"&Calc!$EW10&",",CHAR(34)&INDEX(Settings!$G$6:$G$13,MATCH($F10,Settings!$E$6:$E$13,0))&CHAR(34)&":["&_xlfn.TEXTJOIN(",",TRUE,Calc!$EW10:$FT10)&"],")))&CHAR(34)&"target"&CHAR(34)&":"&$H10&IF($G10="each",","&CHAR(34)&"mode"&CHAR(34)&":"&CHAR(34)&"each"&CHAR(34),"")&"}}") -> {"tileId":80,"taskType":"item_drop","taskConfig":{"item":"Sarachnis cudgel","target":1}}
A11: 79 | B11: =IFERROR(INDEX(Maze!$C$5:$C$85,MATCH($A11,Maze!$A$5:$A$85,0)),"") -> Arm 1 | C11: =IFERROR(INDEX(Maze!$D$5:$D$85,MATCH($A11,Maze!$A$5:$A$85,0)),"") -> 6 | D11: =IFERROR(INDEX(Maze!$E$5:$E$85,MATCH($A11,Maze!$A$5:$A$85,0)),"") -> Skippable | E11: =IFERROR(INDEX(Maze!$G$5:$G$85,MATCH($A11,Maze!$A$5:$A$85,0)),"") -> Yes | F11: npc_kill | H11: 1000 | L11: Giant Mole | AJ11: {=SUMPRODUCT(($L11:$AI11<>"")*1)} -> 1 | AK11: =IF($F11="","",IF($G11="each",$AJ11*$H11,$H11)) -> 1000 | AL11: =IF($F11="","",IFERROR((IF($G11="each",IF($I11="No",SUM(Calc!$BZ11:$CW11),IF($F11="item_drop",SUM(Calc!$DX11:$EU11),IF($I11="Yes",MAX(Calc!$BZ11:$CW11),SUM(Calc!$BZ11:$CW11)))),$H11/MAX(Calc!$BA11:$BX11)))/IF($J11="",cfg_ratemult,$J11),"")) -> 20 | AM11: =IF($AL11="","",$AL11/MAX(0.1,IF($K11="",IF($B11="Arm 1",cfg_arm1,IF($B11="Arm 2",cfg_arm2,IF($B11="Arm 3",cfg_arm3,cfg_concurrent))),$K11))+cfg_overhead/60) -> 20.2 | AN11: =IF($AM11="","",INT($AM11/24)&"d "&TEXT(MOD($AM11,24),"0.0")&"h") -> 0d 20h | AO11: =IF($AM11="","",$AL11*IFERROR(GAMMAINV(cfg_pct,MAX(1,IF($F11="item_drop",IF($G11="each",$AJ11*$H11,$H11),1000)),1/MAX(1,IF($F11="item_drop",IF($G11="each",$AJ11*$H11,$H11),1000))),1)/MAX(0.1,IF($K11="",IF($B11="Arm 1",cfg_arm1,IF($B11="Arm 2",cfg_arm2,IF($B11="Arm 3",cfg_arm3,cfg_concurrent))),$K11))+cfg_overhead/60) -> 21.014686 | AP11: =(cfg_base+cfg_slope*$C11^cfg_exp)*IF($D11="KEY",cfg_mkey,IF($D11="END",cfg_mend,IF($D11="Skippable",cfg_mskip,1))) -> 0.34098807 | AQ11: =IF(OR($AM11="",$AP11=0),"",$AM11/$AP11) -> 59.239609 | AR11: =IF($F11="","- no task set -",_xlfn.TEXTJOIN(" | ",TRUE,IF(AND($F11<>"gp_value",$AJ11=0),"no items selected",""),IF(AND($F11="gp_value",$AJ11=0),"pick a farming method so the ETC can be estimated",""),IF(AND($F11="gp_value",$AJ11>1),"gp_value takes no item list - one method is enough",""),IF(AND($F11="minigame_completion",$AJ11>1),"only 1 minigame per tile",""),IF(OR($H11="",$H11<=0),"target missing",""),IF(SUMPRODUCT(($L11:$AE11<>"")*(Calc!$C11:$Z11=0))>0,"unknown entry - not in catalogue",""),IF(AND($G11="each",$AJ11=1),"each with 1 entry = same as any",""),IF($AL11="","ETC not computable",""))) -> #N/A | AS11: Whack-A-Mole | AT11: =IF($F11="","","{"&CHAR(34)&"tileId"&CHAR(34)&":"&$A11&","&CHAR(34)&"taskType"&CHAR(34)&":"&CHAR(34)&$F11&CHAR(34)&","&CHAR(34)&"taskConfig"&CHAR(34)&":{"&IF($F11="gp_value","",IF($F11="minigame_completion",CHAR(34)&"minigame"&CHAR(34)&":"&CHAR(34)&$L11&CHAR(34)&","&CHAR(34)&"message"&CHAR(34)&":"&CHAR(34)&IFERROR(INDEX(minigame_completion!$J$5:$J$47,MATCH($L11,minigame_completion!$A$5:$A$47,0)),"")&CHAR(34)&",",IF($AJ11=1,CHAR(34)&INDEX(Settings!$F$6:$F$13,MATCH($F11,Settings!$E$6:$E$13,0))&CHAR(34)&":"&Calc!$EW11&",",CHAR(34)&INDEX(Settings!$G$6:$G$13,MATCH($F11,Settings!$E$6:$E$13,0))&CHAR(34)&":["&_xlfn.TEXTJOIN(",",TRUE,Calc!$EW11:$FT11)&"],")))&CHAR(34)&"target"&CHAR(34)&":"&$H11&IF($G11="each",","&CHAR(34)&"mode"&CHAR(34)&":"&CHAR(34)&"each"&CHAR(34),"")&"}}") -> {"tileId":79,"taskType":"npc_kill","taskConfig":{"npc":"Giant Mole","target":1000}}
A12: 81 | B12: =IFERROR(INDEX(Maze!$C$5:$C$85,MATCH($A12,Maze!$A$5:$A$85,0)),"") -> Arm 1 | C12: =IFERROR(INDEX(Maze!$D$5:$D$85,MATCH($A12,Maze!$A$5:$A$85,0)),"") -> 6 | D12: =IFERROR(INDEX(Maze!$E$5:$E$85,MATCH($A12,Maze!$A$5:$A$85,0)),"") -> Forced | E12: =IFERROR(INDEX(Maze!$G$5:$G$85,MATCH($A12,Maze!$A$5:$A$85,0)),"") -> No | F12: npc_kill | H12: 250 | L12: Kraken | AJ12: {=SUMPRODUCT(($L12:$AI12<>"")*1)} -> 1 | AK12: =IF($F12="","",IF($G12="each",$AJ12*$H12,$H12)) -> 250 | AL12: =IF($F12="","",IFERROR((IF($G12="each",IF($I12="No",SUM(Calc!$BZ12:$CW12),IF($F12="item_drop",SUM(Calc!$DX12:$EU12),IF($I12="Yes",MAX(Calc!$BZ12:$CW12),SUM(Calc!$BZ12:$CW12)))),$H12/MAX(Calc!$BA12:$BX12)))/IF($J12="",cfg_ratemult,$J12),"")) -> 4.1666667 | AM12: =IF($AL12="","",$AL12/MAX(0.1,IF($K12="",IF($B12="Arm 1",cfg_arm1,IF($B12="Arm 2",cfg_arm2,IF($B12="Arm 3",cfg_arm3,cfg_concurrent))),$K12))+cfg_overhead/60) -> 4.3666667 | AN12: =IF($AM12="","",INT($AM12/24)&"d "&TEXT(MOD($AM12,24),"0.0")&"h") -> 0d 04h | AO12: =IF($AM12="","",$AL12*IFERROR(GAMMAINV(cfg_pct,MAX(1,IF($F12="item_drop",IF($G12="each",$AJ12*$H12,$H12),1000)),1/MAX(1,IF($F12="item_drop",IF($G12="each",$AJ12*$H12,$H12),1000))),1)/MAX(0.1,IF($K12="",IF($B12="Arm 1",cfg_arm1,IF($B12="Arm 2",cfg_arm2,IF($B12="Arm 3",cfg_arm3,cfg_concurrent))),$K12))+cfg_overhead/60) -> 4.536393 | AP12: =(cfg_base+cfg_slope*$C12^cfg_exp)*IF($D12="KEY",cfg_mkey,IF($D12="END",cfg_mend,IF($D12="Skippable",cfg_mskip,1))) -> 0.61997831 | AQ12: =IF(OR($AM12="",$AP12=0),"",$AM12/$AP12) -> 7.0432571 | AR12: =IF($F12="","- no task set -",_xlfn.TEXTJOIN(" | ",TRUE,IF(AND($F12<>"gp_value",$AJ12=0),"no items selected",""),IF(AND($F12="gp_value",$AJ12=0),"pick a farming method so the ETC can be estimated",""),IF(AND($F12="gp_value",$AJ12>1),"gp_value takes no item list - one method is enough",""),IF(AND($F12="minigame_completion",$AJ12>1),"only 1 minigame per tile",""),IF(OR($H12="",$H12<=0),"target missing",""),IF(SUMPRODUCT(($L12:$AE12<>"")*(Calc!$C12:$Z12=0))>0,"unknown entry - not in catalogue",""),IF(AND($G12="each",$AJ12=1),"each with 1 entry = same as any",""),IF($AL12="","ETC not computable",""))) -> #N/A | AS12: The special kind of anime | AT12: =IF($F12="","","{"&CHAR(34)&"tileId"&CHAR(34)&":"&$A12&","&CHAR(34)&"taskType"&CHAR(34)&":"&CHAR(34)&$F12&CHAR(34)&","&CHAR(34)&"taskConfig"&CHAR(34)&":{"&IF($F12="gp_value","",IF($F12="minigame_completion",CHAR(34)&"minigame"&CHAR(34)&":"&CHAR(34)&$L12&CHAR(34)&","&CHAR(34)&"message"&CHAR(34)&":"&CHAR(34)&IFERROR(INDEX(minigame_completion!$J$5:$J$47,MATCH($L12,minigame_completion!$A$5:$A$47,0)),"")&CHAR(34)&",",IF($AJ12=1,CHAR(34)&INDEX(Settings!$F$6:$F$13,MATCH($F12,Settings!$E$6:$E$13,0))&CHAR(34)&":"&Calc!$EW12&",",CHAR(34)&INDEX(Settings!$G$6:$G$13,MATCH($F12,Settings!$E$6:$E$13,0))&CHAR(34)&":["&_xlfn.TEXTJOIN(",",TRUE,Calc!$EW12:$FT12)&"],")))&CHAR(34)&"target"&CHAR(34)&":"&$H12&IF($G12="each",","&CHAR(34)&"mode"&CHAR(34)&":"&CHAR(34)&"each"&CHAR(34),"")&"}}") -> {"tileId":81,"taskType":"npc_kill","taskConfig":{"npc":"Kraken","target":250}}
A13: 72 | B13: =IFERROR(INDEX(Maze!$C$5:$C$85,MATCH($A13,Maze!$A$5:$A$85,0)),"") -> Arm 1 | C13: =IFERROR(INDEX(Maze!$D$5:$D$85,MATCH($A13,Maze!$A$5:$A$85,0)),"") -> 7 | D13: =IFERROR(INDEX(Maze!$E$5:$E$85,MATCH($A13,Maze!$A$5:$A$85,0)),"") -> Forced | E13: =IFERROR(INDEX(Maze!$G$5:$G$85,MATCH($A13,Maze!$A$5:$A$85,0)),"") -> No | F13: item_drop | H13: 3 | L13: Kbd heads | AJ13: {=SUMPRODUCT(($L13:$AI13<>"")*1)} -> 1 | AK13: =IF($F13="","",IF($G13="each",$AJ13*$H13,$H13)) -> 3 | AL13: =IF($F13="","",IFERROR((IF($G13="each",IF($I13="No",SUM(Calc!$BZ13:$CW13),IF($F13="item_drop",SUM(Calc!$DX13:$EU13),IF($I13="Yes",MAX(Calc!$BZ13:$CW13),SUM(Calc!$BZ13:$CW13)))),$H13/MAX(Calc!$BA13:$BX13)))/IF($J13="",cfg_ratemult,$J13),"")) -> 12.8 | AM13: =IF($AL13="","",$AL13/MAX(0.1,IF($K13="",IF($B13="Arm 1",cfg_arm1,IF($B13="Arm 2",cfg_arm2,IF($B13="Arm 3",cfg_arm3,cfg_concurrent))),$K13))+cfg_overhead/60) -> 13 | AN13: =IF($AM13="","",INT($AM13/24)&"d "&TEXT(MOD($AM13,24),"0.0")&"h") -> 0d 13h | AO13: =IF($AM13="","",$AL13*IFERROR(GAMMAINV(cfg_pct,MAX(1,IF($F13="item_drop",IF($G13="each",$AJ13*$H13,$H13),1000)),1/MAX(1,IF($F13="item_drop",IF($G13="each",$AJ13*$H13,$H13),1000))),1)/MAX(0.1,IF($K13="",IF($B13="Arm 1",cfg_arm1,IF($B13="Arm 2",cfg_arm2,IF($B13="Arm 3",cfg_arm3,cfg_concurrent))),$K13))+cfg_overhead/60) -> 22.908567 | AP13: =(cfg_base+cfg_slope*$C13^cfg_exp)*IF($D13="KEY",cfg_mkey,IF($D13="END",cfg_mend,IF($D13="Skippable",cfg_mskip,1))) -> 0.6778963 | AQ13: =IF(OR($AM13="",$AP13=0),"",$AM13/$AP13) -> 19.176975 | AR13: =IF($F13="","- no task set -",_xlfn.TEXTJOIN(" | ",TRUE,IF(AND($F13<>"gp_value",$AJ13=0),"no items selected",""),IF(AND($F13="gp_value",$AJ13=0),"pick a farming method so the ETC can be estimated",""),IF(AND($F13="gp_value",$AJ13>1),"gp_value takes no item list - one method is enough",""),IF(AND($F13="minigame_completion",$AJ13>1),"only 1 minigame per tile",""),IF(OR($H13="",$H13<=0),"target missing",""),IF(SUMPRODUCT(($L13:$AE13<>"")*(Calc!$C13:$Z13=0))>0,"unknown entry - not in catalogue",""),IF(AND($G13="each",$AJ13=1),"each with 1 entry = same as any",""),IF($AL13="","ETC not computable",""))) -> #N/A | AS13: Gawk gawk 3000 | AT13: =IF($F13="","","{"&CHAR(34)&"tileId"&CHAR(34)&":"&$A13&","&CHAR(34)&"taskType"&CHAR(34)&":"&CHAR(34)&$F13&CHAR(34)&","&CHAR(34)&"taskConfig"&CHAR(34)&":{"&IF($F13="gp_value","",IF($F13="minigame_completion",CHAR(34)&"minigame"&CHAR(34)&":"&CHAR(34)&$L13&CHAR(34)&","&CHAR(34)&"message"&CHAR(34)&":"&CHAR(34)&IFERROR(INDEX(minigame_completion!$J$5:$J$47,MATCH($L13,minigame_completion!$A$5:$A$47,0)),"")&CHAR(34)&",",IF($AJ13=1,CHAR(34)&INDEX(Settings!$F$6:$F$13,MATCH($F13,Settings!$E$6:$E$13,0))&CHAR(34)&":"&Calc!$EW13&",",CHAR(34)&INDEX(Settings!$G$6:$G$13,MATCH($F13,Settings!$E$6:$E$13,0))&CHAR(34)&":["&_xlfn.TEXTJOIN(",",TRUE,Calc!$EW13:$FT13)&"],")))&CHAR(34)&"target"&CHAR(34)&":"&$H13&IF($G13="each",","&CHAR(34)&"mode"&CHAR(34)&":"&CHAR(34)&"each"&CHAR(34),"")&"}}") -> {"tileId":72,"taskType":"item_drop","taskConfig":{"item":"Kbd heads","target":3}}
A14: 63 | B14: =IFERROR(INDEX(Maze!$C$5:$C$85,MATCH($A14,Maze!$A$5:$A$85,0)),"") -> Arm 1 | C14: =IFERROR(INDEX(Maze!$D$5:$D$85,MATCH($A14,Maze!$A$5:$A$85,0)),"") -> 8 | D14: =IFERROR(INDEX(Maze!$E$5:$E$85,MATCH($A14,Maze!$A$5:$A$85,0)),"") -> Forced | E14: =IFERROR(INDEX(Maze!$G$5:$G$85,MATCH($A14,Maze!$A$5:$A$85,0)),"") -> No | F14: item_drop | H14: 1 | L14: Odium shard 1 | M14: Odium shard 2 | N14: Odium shard 3 | AJ14: {=SUMPRODUCT(($L14:$AI14<>"")*1)} -> 3 | AK14: =IF($F14="","",IF($G14="each",$AJ14*$H14,$H14)) -> 1 | AL14: =IF($F14="","",IFERROR((IF($G14="each",IF($I14="No",SUM(Calc!$BZ14:$CW14),IF($F14="item_drop",SUM(Calc!$DX14:$EU14),IF($I14="Yes",MAX(Calc!$BZ14:$CW14),SUM(Calc!$BZ14:$CW14)))),$H14/MAX(Calc!$BA14:$BX14)))/IF($J14="",cfg_ratemult,$J14),"")) -> 5.6888889 | AM14: =IF($AL14="","",$AL14/MAX(0.1,IF($K14="",IF($B14="Arm 1",cfg_arm1,IF($B14="Arm 2",cfg_arm2,IF($B14="Arm 3",cfg_arm3,cfg_concurrent))),$K14))+cfg_overhead/60) -> 5.8888889 | AN14: =IF($AM14="","",INT($AM14/24)&"d "&TEXT(MOD($AM14,24),"0.0")&"h") -> 0d 06h | AO14: =IF($AM14="","",$AL14*IFERROR(GAMMAINV(cfg_pct,MAX(1,IF($F14="item_drop",IF($G14="each",$AJ14*$H14,$H14),1000)),1/MAX(1,IF($F14="item_drop",IF($G14="each",$AJ14*$H14,$H14),1000))),1)/MAX(0.1,IF($K14="",IF($B14="Arm 1",cfg_arm1,IF($B14="Arm 2",cfg_arm2,IF($B14="Arm 3",cfg_arm3,cfg_concurrent))),$K14))+cfg_overhead/60) -> 13.299151 | AP14: =(cfg_base+cfg_slope*$C14^cfg_exp)*IF($D14="KEY",cfg_mkey,IF($D14="END",cfg_mend,IF($D14="Skippable",cfg_mskip,1))) -> 0.74146361 | AQ14: =IF(OR($AM14="",$AP14=0),"",$AM14/$AP14) -> 7.9422494 | AR14: =IF($F14="","- no task set -",_xlfn.TEXTJOIN(" | ",TRUE,IF(AND($F14<>"gp_value",$AJ14=0),"no items selected",""),IF(AND($F14="gp_value",$AJ14=0),"pick a farming method so the ETC can be estimated",""),IF(AND($F14="gp_value",$AJ14>1),"gp_value takes no item list - one method is enough",""),IF(AND($F14="minigame_completion",$AJ14>1),"only 1 minigame per tile",""),IF(OR($H14="",$H14<=0),"target missing",""),IF(SUMPRODUCT(($L14:$AE14<>"")*(Calc!$C14:$Z14=0))>0,"unknown entry - not in catalogue",""),IF(AND($G14="each",$AJ14=1),"each with 1 entry = same as any",""),IF($AL14="","ETC not computable",""))) -> #N/A | AS14: Shard tale | AT14: =IF($F14="","","{"&CHAR(34)&"tileId"&CHAR(34)&":"&$A14&","&CHAR(34)&"taskType"&CHAR(34)&":"&CHAR(34)&$F14&CHAR(34)&","&CHAR(34)&"taskConfig"&CHAR(34)&":{"&IF($F14="gp_value","",IF($F14="minigame_completion",CHAR(34)&"minigame"&CHAR(34)&":"&CHAR(34)&$L14&CHAR(34)&","&CHAR(34)&"message"&CHAR(34)&":"&CHAR(34)&IFERROR(INDEX(minigame_completion!$J$5:$J$47,MATCH($L14,minigame_completion!$A$5:$A$47,0)),"")&CHAR(34)&",",IF($AJ14=1,CHAR(34)&INDEX(Settings!$F$6:$F$13,MATCH($F14,Settings!$E$6:$E$13,0))&CHAR(34)&":"&Calc!$EW14&",",CHAR(34)&INDEX(Settings!$G$6:$G$13,MATCH($F14,Settings!$E$6:$E$13,0))&CHAR(34)&":["&_xlfn.TEXTJOIN(",",TRUE,Calc!$EW14:$FT14)&"],")))&CHAR(34)&"target"&CHAR(34)&":"&$H14&IF($G14="each",","&CHAR(34)&"mode"&CHAR(34)&":"&CHAR(34)&"each"&CHAR(34),"")&"}}") -> {"tileId":63,"taskType":"item_drop","taskConfig":{"items":["Odium shard 1","Odium shard 2","Odium shard 3"],"target":1}}
A15: 54 | B15: =IFERROR(INDEX(Maze!$C$5:$C$85,MATCH($A15,Maze!$A$5:$A$85,0)),"") -> Arm 1 | C15: =IFERROR(INDEX(Maze!$D$5:$D$85,MATCH($A15,Maze!$A$5:$A$85,0)),"") -> 9 | D15: =IFERROR(INDEX(Maze!$E$5:$E$85,MATCH($A15,Maze!$A$5:$A$85,0)),"") -> Forced | E15: =IFERROR(INDEX(Maze!$G$5:$G$85,MATCH($A15,Maze!$A$5:$A$85,0)),"") -> No | F15: item_drop | H15: 5 | L15: Ahrim's hood | M15: Ahrim's robetop | N15: Ahrim's robeskirt | O15: Ahrim's staff | P15: Dharok's helm | Q15: Dharok's platebody | R15: Dharok's platelegs | S15: Dharok's greataxe | T15: Guthan's helm | U15: Guthan's platebody | V15: Guthan's chainskirt | W15: Guthan's warspear | X15: Karil's coif | Y15: Karil's leathertop | Z15: Karil's leatherskirt | AA15: Karil's crossbow | AB15: Torag's helm | AC15: Torag's platebody | AD15: Torag's platelegs | AE15: Torag's hammers | AF15: Verac's helm | AG15: Verac's brassard | AH15: Verac's plateskirt | AI15: Verac's flail | AJ15: {=SUMPRODUCT(($L15:$AI15<>"")*1)} -> 24 | AK15: =IF($F15="","",IF($G15="each",$AJ15*$H15,$H15)) -> 5 | AL15: =IF($F15="","",IFERROR((IF($G15="each",IF($I15="No",SUM(Calc!$BZ15:$CW15),IF($F15="item_drop",SUM(Calc!$DX15:$EU15),IF($I15="Yes",MAX(Calc!$BZ15:$CW15),SUM(Calc!$BZ15:$CW15)))),$H15/MAX(Calc!$BA15:$BX15)))/IF($J15="",cfg_ratemult,$J15),"")) -> 6.0763889 | AM15: =IF($AL15="","",$AL15/MAX(0.1,IF($K15="",IF($B15="Arm 1",cfg_arm1,IF($B15="Arm 2",cfg_arm2,IF($B15="Arm 3",cfg_arm3,cfg_concurrent))),$K15))+cfg_overhead/60) -> 6.2763889 | AN15: =IF($AM15="","",INT($AM15/24)&"d "&TEXT(MOD($AM15,24),"0.0")&"h") -> 0d 06h | AO15: =IF($AM15="","",$AL15*IFERROR(GAMMAINV(cfg_pct,MAX(1,IF($F15="item_drop",IF($G15="each",$AJ15*$H15,$H15),1000)),1/MAX(1,IF($F15="item_drop",IF($G15="each",$AJ15*$H15,$H15),1000))),1)/MAX(0.1,IF($K15="",IF($B15="Arm 1",cfg_arm1,IF($B15="Arm 2",cfg_arm2,IF($B15="Arm 3",cfg_arm3,cfg_concurrent))),$K15))+cfg_overhead/60) -> 9.9144318 | AP15: =(cfg_base+cfg_slope*$C15^cfg_exp)*IF($D15="KEY",cfg_mkey,IF($D15="END",cfg_mend,IF($D15="Skippable",cfg_mskip,1))) -> 0.81042128 | AQ15: =IF(OR($AM15="",$AP15=0),"",$AM15/$AP15) -> 7.7446003 | AR15: =IF($F15="","- no task set -",_xlfn.TEXTJOIN(" | ",TRUE,IF(AND($F15<>"gp_value",$AJ15=0),"no items selected",""),IF(AND($F15="gp_value",$AJ15=0),"pick a farming method so the ETC can be estimated",""),IF(AND($F15="gp_value",$AJ15>1),"gp_value takes no item list - one method is enough",""),IF(AND($F15="minigame_completion",$AJ15>1),"only 1 minigame per tile",""),IF(OR($H15="",$H15<=0),"target missing",""),IF(SUMPRODUCT(($L15:$AE15<>"")*(Calc!$C15:$Z15=0))>0,"unknown entry - not in catalogue",""),IF(AND($G15="each",$AJ15=1),"each with 1 entry = same as any",""),IF($AL15="","ETC not computable",""))) -> #N/A | AS15: Six feet under | AT15: =IF($F15="","","{"&CHAR(34)&"tileId"&CHAR(34)&":"&$A15&","&CHAR(34)&"taskType"&CHAR(34)&":"&CHAR(34)&$F15&CHAR(34)&","&CHAR(34)&"taskConfig"&CHAR(34)&":{"&IF($F15="gp_value","",IF($F15="minigame_completion",CHAR(34)&"minigame"&CHAR(34)&":"&CHAR(34)&$L15&CHAR(34)&","&CHAR(34)&"message"&CHAR(34)&":"&CHAR(34)&IFERROR(INDEX(minigame_completion!$J$5:$J$47,MATCH($L15,minigame_completion!$A$5:$A$47,0)),"")&CHAR(34)&",",IF($AJ15=1,CHAR(34)&INDEX(Settings!$F$6:$F$13,MATCH($F15,Settings!$E$6:$E$13,0))&CHAR(34)&":"&Calc!$EW15&",",CHAR(34)&INDEX(Settings!$G$6:$G$13,MATCH($F15,Settings!$E$6:$E$13,0))&CHAR(34)&":["&_xlfn.TEXTJOIN(",",TRUE,Calc!$EW15:$FT15)&"],")))&CHAR(34)&"target"&CHAR(34)&":"&$H15&IF($G15="each",","&CHAR(34)&"mode"&CHAR(34)&":"&CHAR(34)&"each"&CHAR(34),"")&"}}") -> {"tileId":54,"taskType":"item_drop","taskConfig":{"items":["Ahrim's hood","Ahrim's robetop","Ahrim's robeskirt","Ahrim's staff","Dharok's helm","Dharok's platebody","Dharok's platelegs","Dharok's greataxe","Guthan's helm","Guthan's platebody","Guthan's chainskirt","Guthan's warspear","Karil's coif","Karil's leathertop","Karil's leatherskirt","Karil's crossbow","Torag's helm","Torag's platebody","Torag's platelegs","Torag's hammers","Verac's helm","Verac's brassard","Verac's plateskirt","Verac's flail"],"target":5}}
A16: 45 | B16: =IFERROR(INDEX(Maze!$C$5:$C$85,MATCH($A16,Maze!$A$5:$A$85,0)),"") -> Arm 1 | C16: =IFERROR(INDEX(Maze!$D$5:$D$85,MATCH($A16,Maze!$A$5:$A$85,0)),"") -> 10 | D16: =IFERROR(INDEX(Maze!$E$5:$E$85,MATCH($A16,Maze!$A$5:$A$85,0)),"") -> Forced | E16: =IFERROR(INDEX(Maze!$G$5:$G$85,MATCH($A16,Maze!$A$5:$A$85,0)),"") -> No | F16: npc_kill | G16: each | H16: 100 | L16: Green dragon | M16: Blue dragon | N16: Red dragon | O16: Black dragon | AJ16: {=SUMPRODUCT(($L16:$AI16<>"")*1)} -> 4 | AK16: =IF($F16="","",IF($G16="each",$AJ16*$H16,$H16)) -> 400 | AL16: =IF($F16="","",IFERROR((IF($G16="each",IF($I16="No",SUM(Calc!$BZ16:$CW16),IF($F16="item_drop",SUM(Calc!$DX16:$EU16),IF($I16="Yes",MAX(Calc!$BZ16:$CW16),SUM(Calc!$BZ16:$CW16)))),$H16/MAX(Calc!$BA16:$BX16)))/IF($J16="",cfg_ratemult,$J16),"")) -> 6.0555556 | AM16: =IF($AL16="","",$AL16/MAX(0.1,IF($K16="",IF($B16="Arm 1",cfg_arm1,IF($B16="Arm 2",cfg_arm2,IF($B16="Arm 3",cfg_arm3,cfg_concurrent))),$K16))+cfg_overhead/60) -> 6.2555556 | AN16: =IF($AM16="","",INT($AM16/24)&"d "&TEXT(MOD($AM16,24),"0.0")&"h") -> 0d 06h | AO16: =IF($AM16="","",$AL16*IFERROR(GAMMAINV(cfg_pct,MAX(1,IF($F16="item_drop",IF($G16="each",$AJ16*$H16,$H16),1000)),1/MAX(1,IF($F16="item_drop",IF($G16="each",$AJ16*$H16,$H16),1000))),1)/MAX(0.1,IF($K16="",IF($B16="Arm 1",cfg_arm1,IF($B16="Arm 2",cfg_arm2,IF($B16="Arm 3",cfg_arm3,cfg_concurrent))),$K16))+cfg_overhead/60) -> 6.5022244 | AP16: =(cfg_base+cfg_slope*$C16^cfg_exp)*IF($D16="KEY",cfg_mkey,IF($D16="END",cfg_mend,IF($D16="Skippable",cfg_mskip,1))) -> 0.88455094 | AQ16: =IF(OR($AM16="",$AP16=0),"",$AM16/$AP16) -> 7.0720128 | AR16: =IF($F16="","- no task set -",_xlfn.TEXTJOIN(" | ",TRUE,IF(AND($F16<>"gp_value",$AJ16=0),"no items selected",""),IF(AND($F16="gp_value",$AJ16=0),"pick a farming method so the ETC can be estimated",""),IF(AND($F16="gp_value",$AJ16>1),"gp_value takes no item list - one method is enough",""),IF(AND($F16="minigame_completion",$AJ16>1),"only 1 minigame per tile",""),IF(OR($H16="",$H16<=0),"target missing",""),IF(SUMPRODUCT(($L16:$AE16<>"")*(Calc!$C16:$Z16=0))>0,"unknown entry - not in catalogue",""),IF(AND($G16="each",$AJ16=1),"each with 1 entry = same as any",""),IF($AL16="","ETC not computable",""))) -> #N/A | AS16: Imagine Dragon deez nuts across your face | AT16: =IF($F16="","","{"&CHAR(34)&"tileId"&CHAR(34)&":"&$A16&","&CHAR(34)&"taskType"&CHAR(34)&":"&CHAR(34)&$F16&CHAR(34)&","&CHAR(34)&"taskConfig"&CHAR(34)&":{"&IF($F16="gp_value","",IF($F16="minigame_completion",CHAR(34)&"minigame"&CHAR(34)&":"&CHAR(34)&$L16&CHAR(34)&","&CHAR(34)&"message"&CHAR(34)&":"&CHAR(34)&IFERROR(INDEX(minigame_completion!$J$5:$J$47,MATCH($L16,minigame_completion!$A$5:$A$47,0)),"")&CHAR(34)&",",IF($AJ16=1,CHAR(34)&INDEX(Settings!$F$6:$F$13,MATCH($F16,Settings!$E$6:$E$13,0))&CHAR(34)&":"&Calc!$EW16&",",CHAR(34)&INDEX(Settings!$G$6:$G$13,MATCH($F16,Settings!$E$6:$E$13,0))&CHAR(34)&":["&_xlfn.TEXTJOIN(",",TRUE,Calc!$EW16:$FT16)&"],")))&CHAR(34)&"target"&CHAR(34)&":"&$H16&IF($G16="each",","&CHAR(34)&"mode"&CHAR(34)&":"&CHAR(34)&"each"&CHAR(34),"")&"}}") -> {"tileId":45,"taskType":"npc_kill","taskConfig":{"npcs":["Green dragon","Blue dragon","Red dragon","Black dragon"],"target":100,"mode":"each"}}
A17: 44 | B17: =IFERROR(INDEX(Maze!$C$5:$C$85,MATCH($A17,Maze!$A$5:$A$85,0)),"") -> Arm 1 | C17: =IFERROR(INDEX(Maze!$D$5:$D$85,MATCH($A17,Maze!$A$5:$A$85,0)),"") -> 11 | D17: =IFERROR(INDEX(Maze!$E$5:$E$85,MATCH($A17,Maze!$A$5:$A$85,0)),"") -> Forced | E17: =IFERROR(INDEX(Maze!$G$5:$G$85,MATCH($A17,Maze!$A$5:$A$85,0)),"") -> No | F17: item_drop | G17: each | H17: 1 | L17: Mithril 2h sword | M17: Mud battlestaff | N17: Seercull | AJ17: {=SUMPRODUCT(($L17:$AI17<>"")*1)} -> 3 | AK17: =IF($F17="","",IF($G17="each",$AJ17*$H17,$H17)) -> 3 | AL17: =IF($F17="","",IFERROR((IF($G17="each",IF($I17="No",SUM(Calc!$BZ17:$CW17),IF($F17="item_drop",SUM(Calc!$DX17:$EU17),IF($I17="Yes",MAX(Calc!$BZ17:$CW17),SUM(Calc!$BZ17:$CW17)))),$H17/MAX(Calc!$BA17:$BX17)))/IF($J17="",cfg_ratemult,$J17),"")) -> 3.2 | AM17: =IF($AL17="","",$AL17/MAX(0.1,IF($K17="",IF($B17="Arm 1",cfg_arm1,IF($B17="Arm 2",cfg_arm2,IF($B17="Arm 3",cfg_arm3,cfg_concurrent))),$K17))+cfg_overhead/60) -> 3.4 | AN17: =IF($AM17="","",INT($AM17/24)&"d "&TEXT(MOD($AM17,24),"0.0")&"h") -> 0d 03h | AO17: =IF($AM17="","",$AL17*IFERROR(GAMMAINV(cfg_pct,MAX(1,IF($F17="item_drop",IF($G17="each",$AJ17*$H17,$H17),1000)),1/MAX(1,IF($F17="item_drop",IF($G17="each",$AJ17*$H17,$H17),1000))),1)/MAX(0.1,IF($K17="",IF($B17="Arm 1",cfg_arm1,IF($B17="Arm 2",cfg_arm2,IF($B17="Arm 3",cfg_arm3,cfg_concurrent))),$K17))+cfg_overhead/60) -> 5.8771417 | AP17: =(cfg_base+cfg_slope*$C17^cfg_exp)*IF($D17="KEY",cfg_mkey,IF($D17="END",cfg_mend,IF($D17="Skippable",cfg_mskip,1))) -> 0.96366487 | AQ17: =IF(OR($AM17="",$AP17=0),"",$AM17/$AP17) -> 3.5281975 | AR17: =IF($F17="","- no task set -",_xlfn.TEXTJOIN(" | ",TRUE,IF(AND($F17<>"gp_value",$AJ17=0),"no items selected",""),IF(AND($F17="gp_value",$AJ17=0),"pick a farming method so the ETC can be estimated",""),IF(AND($F17="gp_value",$AJ17>1),"gp_value takes no item list - one method is enough",""),IF(AND($F17="minigame_completion",$AJ17>1),"only 1 minigame per tile",""),IF(OR($H17="",$H17<=0),"target missing",""),IF(SUMPRODUCT(($L17:$AE17<>"")*(Calc!$C17:$Z17=0))>0,"unknown entry - not in catalogue",""),IF(AND($G17="each",$AJ17=1),"each with 1 entry = same as any",""),IF($AL17="","ETC not computable",""))) -> #N/A | AS17: Lotr but different | AT17: =IF($F17="","","{"&CHAR(34)&"tileId"&CHAR(34)&":"&$A17&","&CHAR(34)&"taskType"&CHAR(34)&":"&CHAR(34)&$F17&CHAR(34)&","&CHAR(34)&"taskConfig"&CHAR(34)&":{"&IF($F17="gp_value","",IF($F17="minigame_completion",CHAR(34)&"minigame"&CHAR(34)&":"&CHAR(34)&$L17&CHAR(34)&","&CHAR(34)&"message"&CHAR(34)&":"&CHAR(34)&IFERROR(INDEX(minigame_completion!$J$5:$J$47,MATCH($L17,minigame_completion!$A$5:$A$47,0)),"")&CHAR(34)&",",IF($AJ17=1,CHAR(34)&INDEX(Settings!$F$6:$F$13,MATCH($F17,Settings!$E$6:$E$13,0))&CHAR(34)&":"&Calc!$EW17&",",CHAR(34)&INDEX(Settings!$G$6:$G$13,MATCH($F17,Settings!$E$6:$E$13,0))&CHAR(34)&":["&_xlfn.TEXTJOIN(",",TRUE,Calc!$EW17:$FT17)&"],")))&CHAR(34)&"target"&CHAR(34)&":"&$H17&IF($G17="each",","&CHAR(34)&"mode"&CHAR(34)&":"&CHAR(34)&"each"&CHAR(34),"")&"}}") -> {"tileId":44,"taskType":"item_drop","taskConfig":{"items":["Mithril 2h sword","Mud battlestaff","Seercull"],"target":1,"mode":"each"}}
A18: 43 | B18: =IFERROR(INDEX(Maze!$C$5:$C$85,MATCH($A18,Maze!$A$5:$A$85,0)),"") -> Arm 1 | C18: =IFERROR(INDEX(Maze!$D$5:$D$85,MATCH($A18,Maze!$A$5:$A$85,0)),"") -> 12 | D18: =IFERROR(INDEX(Maze!$E$5:$E$85,MATCH($A18,Maze!$A$5:$A$85,0)),"") -> Forced | E18: =IFERROR(INDEX(Maze!$G$5:$G$85,MATCH($A18,Maze!$A$5:$A$85,0)),"") -> No | F18: item_drop | H18: 3 | L18: Unsired | AJ18: {=SUMPRODUCT(($L18:$AI18<>"")*1)} -> 1 | AK18: =IF($F18="","",IF($G18="each",$AJ18*$H18,$H18)) -> 3 | AL18: =IF($F18="","",IFERROR((IF($G18="each",IF($I18="No",SUM(Calc!$BZ18:$CW18),IF($F18="item_drop",SUM(Calc!$DX18:$EU18),IF($I18="Yes",MAX(Calc!$BZ18:$CW18),SUM(Calc!$BZ18:$CW18)))),$H18/MAX(Calc!$BA18:$BX18)))/IF($J18="",cfg_ratemult,$J18),"")) -> 7.6923077 | AM18: =IF($AL18="","",$AL18/MAX(0.1,IF($K18="",IF($B18="Arm 1",cfg_arm1,IF($B18="Arm 2",cfg_arm2,IF($B18="Arm 3",cfg_arm3,cfg_concurrent))),$K18))+cfg_overhead/60) -> 7.8923077 | AN18: =IF($AM18="","",INT($AM18/24)&"d "&TEXT(MOD($AM18,24),"0.0")&"h") -> 0d 08h | AO18: =IF($AM18="","",$AL18*IFERROR(GAMMAINV(cfg_pct,MAX(1,IF($F18="item_drop",IF($G18="each",$AJ18*$H18,$H18),1000)),1/MAX(1,IF($F18="item_drop",IF($G18="each",$AJ18*$H18,$H18),1000))),1)/MAX(0.1,IF($K18="",IF($B18="Arm 1",cfg_arm1,IF($B18="Arm 2",cfg_arm2,IF($B18="Arm 3",cfg_arm3,cfg_concurrent))),$K18))+cfg_overhead/60) -> 13.846975 | AP18: =(cfg_base+cfg_slope*$C18^cfg_exp)*IF($D18="KEY",cfg_mkey,IF($D18="END",cfg_mend,IF($D18="Skippable",cfg_mskip,1))) -> 1.0475992 | AQ18: =IF(OR($AM18="",$AP18=0),"",$AM18/$AP18) -> 7.533709 | AR18: =IF($F18="","- no task set -",_xlfn.TEXTJOIN(" | ",TRUE,IF(AND($F18<>"gp_value",$AJ18=0),"no items selected",""),IF(AND($F18="gp_value",$AJ18=0),"pick a farming method so the ETC can be estimated",""),IF(AND($F18="gp_value",$AJ18>1),"gp_value takes no item list - one method is enough",""),IF(AND($F18="minigame_completion",$AJ18>1),"only 1 minigame per tile",""),IF(OR($H18="",$H18<=0),"target missing",""),IF(SUMPRODUCT(($L18:$AE18<>"")*(Calc!$C18:$Z18=0))>0,"unknown entry - not in catalogue",""),IF(AND($G18="each",$AJ18=1),"each with 1 entry = same as any",""),IF($AL18="","ETC not computable",""))) -> #N/A | AS18: They're stackable now | AT18: =IF($F18="","","{"&CHAR(34)&"tileId"&CHAR(34)&":"&$A18&","&CHAR(34)&"taskType"&CHAR(34)&":"&CHAR(34)&$F18&CHAR(34)&","&CHAR(34)&"taskConfig"&CHAR(34)&":{"&IF($F18="gp_value","",IF($F18="minigame_completion",CHAR(34)&"minigame"&CHAR(34)&":"&CHAR(34)&$L18&CHAR(34)&","&CHAR(34)&"message"&CHAR(34)&":"&CHAR(34)&IFERROR(INDEX(minigame_completion!$J$5:$J$47,MATCH($L18,minigame_completion!$A$5:$A$47,0)),"")&CHAR(34)&",",IF($AJ18=1,CHAR(34)&INDEX(Settings!$F$6:$F$13,MATCH($F18,Settings!$E$6:$E$13,0))&CHAR(34)&":"&Calc!$EW18&",",CHAR(34)&INDEX(Settings!$G$6:$G$13,MATCH($F18,Settings!$E$6:$E$13,0))&CHAR(34)&":["&_xlfn.TEXTJOIN(",",TRUE,Calc!$EW18:$FT18)&"],")))&CHAR(34)&"target"&CHAR(34)&":"&$H18&IF($G18="each",","&CHAR(34)&"mode"&CHAR(34)&":"&CHAR(34)&"each"&CHAR(34),"")&"}}") -> {"tileId":43,"taskType":"item_drop","taskConfig":{"item":"Unsired","target":3}}
